Workbook

Sheet 광양터미널_2026
A1: 🌊 광양터미널 월간운영 실적 (2026)
A2: Gwangyang Terminal Monthly Operations Report — Storage · Discharge · Bunkering · Trade
A4: 구역 | B4: 월 | C4: 운영지표 | D4: 단위 | E4: 1탱크 | F4: 2탱크 | G4: 3탱크 | H4: 4탱크 | I4: 5탱크 | J4: 6탱크 | K4: 합계 | L4: 전월대비(%) | M4: 비고
A5: 광양 1구역 | B5: 2026-01 | C5: 저장량 | D5: 천톤 | E5: 73 | F5: 72 | G5: 67 | H5: 72 | I5: 77 | J5: 18 | K5: =SUM(E5:J5) -> 379 | L5: - | M5: 최적 재고
A6: 광양 1구역 | B6: 2026-01 | C6: 송출량 | D6: 천톤 | E6: 42 | F6: 40 | G6: 45 | H6: 41 | I6: 46 | J6: 7 | K6: =SUM(E6:J6) -> 221 | L6: - | M6: 수요 견조
A7: 광양 1구역 | B7: 2026-01 | C7: 벙커링 | D7: 톤 | E7: 0 | F7: 0 | G7: 0 | H7: 0 | I7: 1907 | J7: 0 | K7: =SUM(E7:J7) -> 1907 | L7: - | M7: 주2회 운영
A8: 광양 1구역 | B8: 2026-01 | C8: 반출입 | D8: 톤 | E8: 0 | F8: 0 | G8: 0 | H8: 0 | I8: 0 | J8: 3262 | K8: =SUM(E8:J8) -> 3262 | L8: - | M8: 제2터미널 부두
A9: 광양 1구역 | B9: 2026-02 | C9: 저장량 | D9: 천톤 | E9: 74 | F9: 72 | G9: 70 | H9: 73 | I9: 74 | J9: 31 | K9: =SUM(E9:J9) -> 394 | L9: =IFERROR((K9-K5)/K5,0) -> 0.039577836 | M9: 비축량 양호
A10: 광양 1구역 | B10: 2026-02 | C10: 송출량 | D10: 천톤 | E10: 46 | F10: 43 | G10: 43 | H10: 48 | I10: 47 | J10: 14 | K10: =SUM(E10:J10) -> 241 | L10: =IFERROR((K10-K6)/K6,0) -> 0.090497738
A11: 광양 1구역 | B11: 2026-02 | C11: 벙커링 | D11: 톤 | E11: 0 | F11: 0 | G11: 0 | H11: 0 | I11: 2141 | J11: 0 | K11: =SUM(E11:J11) -> 2141 | L11: =IFERROR((K11-K7)/K7,0) -> 0.12270582 | M11: 정기 운항
A12: 광양 1구역 | B12: 2026-02 | C12: 반출입 | D12: 톤 | E12: 0 | F12: 0 | G12: 0 | H12: 0 | I12: 0 | J12: 4387 | K12: =SUM(E12:J12) -> 4387 | L12: =IFERROR((K12-K8)/K8,0) -> 0.34488044 | M12: 물동량 증가세
A13: 광양 1구역 | B13: 2026-03 | C13: 저장량 | D13: 천톤 | E13: 80 | F13: 78 | G13: 72 | H13: 80 | I13: 73 | J13: 45 | K13: =SUM(E13:J13) -> 428 | L13: =IFERROR((K13-K9)/K9,0) -> 0.086294416 | M13: 물량 회전율 우수
A14: 광양 1구역 | B14: 2026-03 | C14: 송출량 | D14: 천톤 | E14: 55 | F14: 49 | G14: 47 | H14: 52 | I14: 51 | J14: 25 | K14: =SUM(E14:J14) -> 279 | L14: =IFERROR((K14-K10)/K10,0) -> 0.15767635 | M14: 출하 원활
A15: 광양 1구역 | B15: 2026-03 | C15: 벙커링 | D15: 톤 | E15: 0 | F15: 0 | G15: 0 | H15: 0 | I15: 2575 | J15: 0 | K15: =SUM(E15:J15) -> 2575 | L15: =IFERROR((K15-K11)/K11,0) -> 0.20270901 | M15: 스팟 추가
A16: 광양 1구역 | B16: 2026-03 | C16: 반출입 | D16: 톤 | E16: 0 | F16: 0 | G16: 0 | H16: 0 | I16: 0 | J16: 6137 | K16: =SUM(E16:J16) -> 6137 | L16: =IFERROR((K16-K12)/K12,0) -> 0.39890586 | M16: 동남아 거래 확대
A17: 광양 1구역 | B17: 2026-04 | C17: 저장량 | D17: 천톤 | E17: 78 | F17: 73 | G17: 73 | H17: 74 | I17: 77 | J17: 57 | K17: =SUM(E17:J17) -> 432 | L17: =IFERROR((K17-K13)/K13,0) -> 0.0093457944 | M17: 비축량 양호
A18: 광양 1구역 | B18: 2026-04 | C18: 송출량 | D18: 천톤 | E18: 48 | F18: 44 | G18: 42 | H18: 48 | I18: 50 | J18: 30 | K18: =SUM(E18:J18) -> 262 | L18: =IFERROR((K18-K14)/K14,0) -> -0.0609319
A19: 광양 1구역 | B19: 2026-04 | C19: 벙커링 | D19: 톤 | E19: 0 | F19: 0 | G19: 0 | H19: 0 | I19: 2322 | J19: 0 | K19: =SUM(E19:J19) -> 2322 | L19: =IFERROR((K19-K15)/K15,0) -> -0.098252427 | M19: 월간 최대치
A20: 광양 1구역 | B20: 2026-04 | C20: 반출입 | D20: 톤 | E20: 0 | F20: 0 | G20: 0 | H20: 0 | I20: 0 | J20: 7266 | K20: =SUM(E20:J20) -> 7266 | L20: =IFERROR((K20-K16)/K16,0) -> 0.18396611 | M20: 신규 고객 확보
A21: 광양 1구역 | B21: 2026-05 | C21: 저장량 | D21: 천톤 | E21: 71 | F21: 67 | G21: 71 | H21: 74 | I21: 74 | J21: 68 | K21: =SUM(E21:J21) -> 425 | L21: =IFERROR((K21-K17)/K17,0) -> -0.016203704 | M21: 최적 재고
A22: 광양 1구역 | B22: 2026-05 | C22: 송출량 | D22: 천톤 | E22: 46 | F22: 41 | G22: 37 | H22: 43 | I22: 44 | J22: 33 | K22: =SUM(E22:J22) -> 244 | L22: =IFERROR((K22-K18)/K18,0) -> -0.06870229 | M22: 수요 견조
A23: 광양 1구역 | B23: 2026-05 | C23: 벙커링 | D23: 톤 | E23: 0 | F23: 0 | G23: 0 | H23: 0 | I23: 2112 | J23: 0 | K23: =SUM(E23:J23) -> 2112 | L23: =IFERROR((K23-K19)/K19,0) -> -0.090439276 | M23: 정기 운항
A24: 광양 1구역 | B24: 2026-05 | C24: 반출입 | D24: 톤 | E24: 0 | F24: 0 | G24: 0 | H24: 0 | I24: 0 | J24: 9214 | K24: =SUM(E24:J24) -> 9214 | L24: =IFERROR((K24-K20)/K20,0) -> 0.26809799 | M24: 제2터미널 부두
A25: 광양 1구역 | B25: 2026-06 | C25: 저장량 | D25: 천톤 | E25: 78 | F25: 76 | G25: 75 | H25: 75 | I25: 70 | J25: 77 | K25: =SUM(E25:J25) -> 451 | L25: =IFERROR((K25-K21)/K21,0) -> 0.061176471 | M25: 최적 재고
A26: 광양 1구역 | B26: 2026-06 | C26: 송출량 | D26: 천톤 | E26: 39 | F26: 37 | G26: 35 | H26: 40 | I26: 42 | J26: 45 | K26: =SUM(E26:J26) -> 238 | L26: =IFERROR((K26-K22)/K22,0) -> -0.024590164 | M26: 글로벌 수요 증가
A27: 광양 1구역 | B27: 2026-06 | C27: 벙커링 | D27: 톤 | E27: 0 | F27: 0 | G27: 0 | H27: 0 | I27: 1988 | J27: 0 | K27: =SUM(E27:J27) -> 1988 | L27: =IFERROR((K27-K23)/K23,0) -> -0.058712121 | M27: 벙커링선 주1회
A28: 광양 1구역 | B28: 2026-06 | C28: 반출입 | D28: 톤 | E28: 0 | F28: 0 | G28: 0 | H28: 0 | I28: 0 | J28: 9089 | K28: =SUM(E28:J28) -> 9089 | L28: =IFERROR((K28-K24)/K24,0) -> -0.013566312 | M28: 물동량 증가세
A29: 광양 1구역 | B29: 2026-07 | C29: 저장량 | D29: 천톤 | E29: 80 | F29: 75 | G29: 78 | H29: 81 | I29: 73 | J29: 77 | K29: =SUM(E29:J29) -> 464 | L29: =IFERROR((K29-K25)/K25,0) -> 0.028824834 | M29: 물량 회전율 우수
A30: 광양 1구역 | B30: 2026-07 | C30: 송출량 | D30: 천톤 | E30: 76 | F30: 71 | G30: 70 | H30: 76 | I30: 77 | J30: 80 | K30: =SUM(E30:J30) -> 450 | L30: =IFERROR((K30-K26)/K26,0) -> 0.8907563 | M30: 공급 확대
... A32: 광양 1구역 | B32: 2026-07 | C32: 반출입 | D32: 톤 | E32: 0 | F32: 0 | G32: 0 | H32: 0 | I32: 0 | J32: 11362 | K32: =SUM(E32:J32) -> 11362 | L32: =IFERROR((K32-K28)/K28,0) -> 0.25008252 | M32: 제2터미널 부두
A33: 광양 1구역 | B33: 2026-08 | C33: 저장량 | D33: 천톤 | E33: 70 | F33: 68 | G33: 68 | H33: 70 | I33: 67 | J33: 70 | K33: =SUM(E33:J33) -> 413 | L33: =IFERROR((K33-K29)/K29,0) -> -0.10991379
A34: 광양 1구역 | B34: 2026-08 | C34: 송출량 | D34: 천톤 | E34: 86 | F34: 85 | G34: 78 | H34: 80 | I34: 90 | J34: 92 | K34: =SUM(E34:J34) -> 511 | L34: =IFERROR((K34-K30)/K30,0) -> 0.13555556
A35: 광양 1구역 | B35: 2026-08 | C35: 벙커링 | D35: 톤 | E35: 0 | F35: 0 | G35: 0 | H35: 0 | I35: 2555 | J35: 0 | K35: =SUM(E35:J35) -> 2555 | L35: =IFERROR((K35-K31)/K31,0) -> 0.063696919 | M35: 벙커링선 주1회
A36: 광양 1구역 | B36: 2026-08 | C36: 반출입 | D36: 톤 | E36: 0 | F36: 0 | G36: 0 | H36: 0 | I36: 0 | J36: 11507 | K36: =SUM(E36:J36) -> 11507 | L36: =IFERROR((K36-K32)/K32,0) -> 0.012761838 | M36: 물동량 증가세
A37: 광양 1구역 | B37: 2026-09 | C37: 저장량 | D37: 천톤 | E37: 78 | F37: 77 | G37: 71 | H37: 76 | I37: 70 | J37: 74 | K37: =SUM(E37:J37) -> 446 | L37: =IFERROR((K37-K33)/K33,0) -> 0.079903148
A38: 광양 1구역 | B38: 2026-09 | C38: 송출량 | D38: 천톤 | E38: 58 | F38: 55 | G38: 52 | H38: 54 | I38: 58 | J38: 61 | K38: =SUM(E38:J38) -> 338 | L38: =IFERROR((K38-K34)/K34,0) -> -0.33855186 | M38: 출하량 호조
A39: 광양 1구역 | B39: 2026-09 | C39: 벙커링 | D39: 톤 | E39: 0 | F39: 0 | G39: 0 | H39: 0 | I39: 2281 | J39: 0 | K39: =SUM(E39:J39) -> 2281 | L39: =IFERROR((K39-K35)/K35,0) -> -0.1072407 | M39: 주2회 운영
A40: 광양 1구역 | B40: 2026-09 | C40: 반출입 | D40: 톤 | E40: 0 | F40: 0 | G40: 0 | H40: 0 | I40: 0 | J40: 12476 | K40: =SUM(E40:J40) -> 12476 | L40: =IFERROR((K40-K36)/K36,0) -> 0.084209612 | M40: 물동량 증가세
A41: 광양 1구역 | B41: 2026-10 | C41: 저장량 | D41: 천톤 | E41: 81 | F41: 78 | G41: 79 | H41: 77 | I41: 79 | J41: 80 | K41: =SUM(E41:J41) -> 474 | L41: =IFERROR((K41-K37)/K37,0) -> 0.062780269 | M41: 비축량 양호
A42: 광양 1구역 | B42: 2026-10 | C42: 송출량 | D42: 천톤 | E42: 39 | F42: 38 | G42: 35 | H42: 40 | I42: 42 | J42: 42 | K42: =SUM(E42:J42) -> 236 | L42: =IFERROR((K42-K38)/K38,0) -> -0.30177515 | M42: 출하량 호조
...

Sheet 📊 구역별_요약
A1: 🌊 구역별 연간 요약 (2026)
A3: 구역 | B3: 저장량 합계(천톤) | C3: 송출량 합계(천톤) | D3: 벙커링 합계(톤) | E3: 반출입 합계(톤) | F3: 평균 가동률(%) | G3: 비고
A4: 광양 1구역 | B4: =SUMIFS(광양터미널_2026!K5:K52,광양터미널_2026!C5:C52,"저장량") -> 5320 | C4: =SUMIFS(광양터미널_2026!K5:K52,광양터미널_2026!C5:C52,"송출량") -> 3801 | D4: =SUMIFS(광양터미널_2026!K5:K52,광양터미널_2026!C5:C52,"벙커링") -> 28507 | E4: =SUMIFS(광양터미널_2026!K5:K52,광양터미널_2026!C5:C52,"반출입") -> 116875 | F4: 89.5 | G4: 주력 구역 - 안정적 운영
A5: 광양 2구역 | B5: =SUMIFS(광양터미널_2026!K53:K100,광양터미널_2026!C53:C100,"저장량") -> 4907 | C5: =SUMIFS(광양터미널_2026!K53:K100,광양터미널_2026!C53:C100,"송출량") -> 3502 | D5: =SUMIFS(광양터미널_2026!K53:K100,광양터미널_2026!C53:C100,"벙커링") -> 26237 | E5: =SUMIFS(광양터미널_2026!K53:K100,광양터미널_2026!C53:C100,"반출입") -> 107500 | F5: 88.1 | G5: 확장 구역 - 가동률 상승 추세
A6: 광양 3구역 | B6: =SUMIFS(광양터미널_2026!K101:K148,광양터미널_2026!C101:C148,"저장량") -> 5779 | C6: =SUMIFS(광양터미널_2026!K101:K148,광양터미널_2026!C101:C148,"송출량") -> 4115 | D6: =SUMIFS(광양터미널_2026!K101:K148,광양터미널_2026!C101:C148,"벙커링") -> 30475 | E6: =SUMIFS(광양터미널_2026!K101:K148,광양터미널_2026!C101:C148,"반출입") -> 125454 | F6: 87 | G6: 신규 구역 - 거래 다각화
A7: 광양 4구역 | B7: =SUMIFS(광양터미널_2026!K149:K196,광양터미널_2026!C149:C196,"저장량") -> 4537 | C7: =SUMIFS(광양터미널_2026!K149:K196,광양터미널_2026!C149:C196,"송출량") -> 3218 | D7: =SUMIFS(광양터미널_2026!K149:K196,광양터미널_2026!C149:C196,"벙커링") -> 24124 | E7: =SUMIFS(광양터미널_2026!K149:K196,광양터미널_2026!C149:C196,"반출입") -> 99908 | F7: 91.8 | G7: 전략 구역 - 글로벌 거점
A8: 전체 합계 | B8: =SUM(B4:B7) -> 20543 | C8: =SUM(C4:C7) -> 14636 | D8: =SUM(D4:D7) -> 109343 | E8: =SUM(E4:E7) -> 449737 | F8: =AVERAGE(F4:F7) -> 89.1 | G8: 2026 연간 합산 실적
